Workbook
Name _Hlk140489412: 'Lot 1 - SONGON - DQE'!$A$3
Name D: FERRAILLEURS!$E:$E

Sheet Lot 1 - SONGON - DQE
A1: DETAILS QUANTITATIFS ET ESTIMATIFS (DQE) DU LOT 1
A3: Site 01: Station de traitement des boues de vidange de la ville Abidjan Ouest (Songon)
A5: N° PRIX | B5: DESIGNATION | C5: UNITE | D5: QUANTITE | E5: PRIX UNITAIRE (FCFA) | F5: PRIX TOTAL (FCFA)
A6: SECTION 000 | B6: INSTALLATION GENERALE DE CHANTIER
A7: 000.1 | B7: Installation générale de chantier et des services généraux de l'entreprise, y compris amenée et replis du matériel | C7: fft | D7: 1 | E7: 50000000 | F7: =D7*E7 -> 50000000
A8: Sous total 000 | F8: =SUM(F7) -> 50000000
A9: SECTION 100 | B9: TERRASSEMENTS GENERAUX
A10: 100.1 | B10: Débroussement mécanique
A11: 100.1.1 | B11: Débroussement mécanique y compris abattage d'arbre | C11: m2 | D11: 20400 | E11: 200 | F11: =D11*E11 -> 4080000
A12: 100.1.2 | B12: Enlèvement d'ordures et mise en décharge de tout genre | C12: m3 | D12: 1500 | E12: 4000 | F12: =D12*E12 -> 6000000
A13: 100.2.3 | B13: Décapage de terre végétale sur 0,2 m en moyenne | C13: m2 | D13: 20400 | E13: 400 | F13: =D13*E13 -> 8160000
A14: 100.2 | B14: Démolition
A15: 100.2.1 | B15: Démolition de constructions existantes en maçonnerie | C15: m2 | D15: 10800 | E15: 3000 | F15: =D15*E15 -> 32400000
A16: 100.2.2 | B16: Démolition d'ouvrages en béton armé | C16: m3 | D16: 200 | E16: 20000 | F16: =D16*E16 -> 4000000
A17: Sous total 100 | F17: =SUM(F11:F16) -> 54640000
A18: SECTION 200 | B18: AIRE DE DEPOTAGE, OUVRAGES DE RECEPTION ET DE PRETRAITEMENT
A19: 200.1 | B19: Aire de dépotage y compris muret d'arrêt des camions
A20: 200.1.1 | B20: Déblais en terrain de toute nature, mise en dépôt et évacuation des déblais excédentaires | C20: m3 | D20: 1250 | E20: 3200 | F20: =D20*E20 -> 4000000
A21: 200.1.2 | B21: Remblais provenant de déblais | C21: m3 | D21: 220 | E21: 3100 | F21: =D21*E21 -> 682000
A22: 200.1.3 | B22: Béton de propreté C 150 | C22: m3 | D22: 25 | E22: 80000 | F22: =D22*E22 -> 2000000
A23: 200.1.4 | B23: Béton de qualité Q 350 au ciment CPA | C23: m3 | D23: 50 | E23: 120000 | F23: =D23*E23 -> 6000000
A24: 200.1.5 | B24: Coffrages plans ordinaires | C24: m2 | D24: 25 | E24: 7000 | F24: =D24*E24 -> 175000
A25: 200.1.6 | B25: Aciers à haute adhérence | C25: kg | D25: 4500 | E25: 1150 | F25: =D25*E25 -> 5175000
A26: 200.2 | B26: Ouvrages de dépotage et bac d'observation | F26: =D26*E26 -> 0
A27: 200.1.1 | B27: Déblais en terrain de toute nature, mise en dépôt et évacuation des déblais excédentaires | C27: m3 | D27: 40 | E27: 3200 | F27: =D27*E27 -> 128000
A28: 200.1.2 | B28: Remblais provenant de déblais | C28: m3 | D28: 20 | E28: 3100 | F28: =D28*E28 -> 62000
A29: 200.1.3 | B29: Béton de propreté C 150 | C29: m3 | D29: 15 | E29: 80000 | F29: =D29*E29 -> 1200000
A30: 200.1.4 | B30: Béton de qualité Q 350 au ciment CPA | C30: m3 | D30: 45 | E30: 120000 | F30: =D30*E30 -> 5400000
A31: 200.1.5 | B31: Coffrages plans ordinaires | C31: m2 | D31: 200 | E31: 7000 | F31: =D31*E31 -> 1400000
A32: 200.1.6 | B32: Aciers à haute adhérence | C32: kg | D32: 3150 | E32: 1150 | F32: =D32*E32 -> 3622500
A33: 200.3 | B33: Canal dégrilleur + dallage au droit des ouvrages +muret | F33: =D33*E33 -> 0
A34: 200.1.1 | B34: Déblais en terrain de toute nature, mise en dépôt et évacuation des déblais excédentaires | C34: m3 | D34: 50 | E34: 3200 | F34: =D34*E34 -> 160000
A35: 200.1.2 | B35: Remblais provenant de déblais | C35: m3 | D35: 10 | E35: 3100 | F35: =D35*E35 -> 31000
A36: 200.1.3 | B36: Béton de propreté C 150 | C36: m3 | D36: 5 | E36: 80000 | F36: =D36*E36 -> 400000
A37: 200.1.4 | B37: Béton de qualité Q 350 au ciment CPA | C37: m3 | D37: 15 | E37: 120000 | F37: =D37*E37 -> 1800000
A38: 200.1.5 | B38: Coffrages plans ordinaires | C38: m2 | D38: 20 | E38: 7000 | F38: =D38*E38 -> 140000
A39: 200.1.6 | B39: Aciers à haute adhérence | C39: kg | D39: 1050 | E39: 1150 | F39: =D39*E39 -> 1207500
A40: 200.4 | B40: Canal dessableur | F40: =D40*E40 -> 0
A41: 200.1.1 | B41: Déblais en terrain de toute nature, mise en dépôt et évacuation des déblais excédentaires | C41: m3 | D41: 10 | E41: 3200 | F41: =D41*E41 -> 32000
A42: 200.1.2 | B42: Remblais provenant de déblais | C42: m3 | D42: 5 | E42: 3100 | F42: =D42*E42 -> 15500
...

Sheet Feuil2
B2: FICHIER DE SUIVI DE LA PRODUCTION - SONGON
D5: MARCHE | G5: TRAVAUX REALISES | K5: PRODUCTION
B6: SECTION 300 | C6: LITS DE SECHAGE | D6: Unité | E6: Qté | F6: Prix Unitaire | G6: CUMUL PRECEDENT | H6: TRAVAUX DU JOUR | I6: CUMUL ACTUEL | J6: RESTE A REALISER | K6: (FCFA)
B7: 300.1 | C7: Terrassement généraux
B8: 200.1.1 | C8: Déblais en terrain de toute nature, mise en dépôt et évacuation des déblais excédentaires | D8: m3 | E8: 5350 | F8: 3200 | I8: =+G8+H8 -> 0 | J8: =+E8-I8 -> 5350 | K8: =+I8*F8 -> 0
B9: 200.1.2 | C9: Remblais provenant de déblais | D9: m3 | E9: 1850 | F9: 3100 | I9: =+G9+H9 -> 0 | J9: =+E9-I9 -> 1850 | K9: =+I9*F9 -> 0
B10: 300.1.3 | C10: Remblais provenant d'emprunts | D10: m3 | E10: 1350 | F10: 10000 | I10: =+G10+H10 -> 0 | J10: =+E10-I10 -> 1350 | K10: =+I10*F10 -> 0
B11: 300.2 | C11: Génie-Civil des lits de séchage y compris rampes d'accès
B12: 200.1.3 | C12: Béton de propreté C 150 | D12: m3 | E12: 180 | F12: 80000 | I12: =+G12+H12 -> 0 | J12: =+E12-I12 -> 180 | K12: =+I12*F12 -> 0
B13: 200.1.4 | C13: Béton de qualité Q 350 au ciment CPA | D13: m3 | E13: 600 | F13: 120000 | I13: =+G13+H13 -> 0 | J13: =+E13-I13 -> 600 | K13: =+I13*F13 -> 0
B14: 200.1.5 | C14: Coffrages plans ordinaires | D14: m2 | E14: 1100 | F14: 7000 | I14: =+G14+H14 -> 0 | J14: =+E14-I14 -> 1100 | K14: =+I14*F14 -> 0
B15: 200.1.8 | C15: Coffrages soignée | D15: m2 | E15: 950 | F15: 8000 | I15: =+G15+H15 -> 0 | J15: =+E15-I15 -> 950 | K15: =+I15*F15 -> 0
B16: 200.1.6 | C16: Aciers à haute adhérence | D16: kg | E16: 54000 | F16: 1150 | I16: =+G16+H16 -> 0 | J16: =+E16-I16 -> 54000 | K16: =+I16*F16 -> 0
B17: 300.2.1 | C17: Badigeonnage des parements enterrés | D17: m2 | E17: 1250 | F17: 800 | I17: =+G17+H17 -> 0 | J17: =+E17-I17 -> 1250 | K17: =+I17*F17 -> 0
B18: TOTAL | K18: =SUM(K8:K17) -> 0

Sheet Instruction
B2: Instruction relatives à l'utilisation du fichier
B4: 1. Prière de renseigner uniquement les fuilles des ouvriers (Maçons, ferrailleurs, coffreurs, etc.)
B6: 2. Pour les présents, renseigner "1" sinon "0"
B8: 3. La feuille "SUIVI HEBDOMADAIRE PAIE" sera renseigner automatiquement.

Sheet SUIVI HEBDOMADAIRE PAIE
A2: SUIVI HEBDOMADAIRE DE LA PAIE DE LA MAIN D'ŒUVRE / SEMAINE DU 03 AU 09/07/2026
A4: N° | B4: DESIGNATION | C4: SALAIRE UNITAIRE | D4: VENDREDI | F4: SAMEDI | H4: DIMANCHE | J4: LUNDI | L4: MARDI | N4: MERCREDI | P4: JEUDI | R4: MONTANT TOTAL BRUT | S4: RETENUE EPI | T4: NET A PAYER
D5: EFFECTIF PRESENTS | E5: MONTANT | F5: EFFECTIF PRESENTS | G5: MONTANT | H5: EFFECTIF PRESENTS | I5: MONTANT | J5: EFFECTIF PRESENTS | K5: MONTANT | L5: EFFECTIF PRESENTS | M5: MONTANT | N5: EFFECTIF PRESENTS | O5: MONTANT | P5: EFFECTIF PRESENTS | Q5: MONTANT | S5: EPI
A6: JOURNAMIERS
A7: 1 | B7: MACONS | C7: 7500 | D7: =+MACONS!D31 -> 4 | E7: =+MACONS!E31 -> 31000 | F7: =+MACONS!F31 -> 4 | G7: =+MACONS!G31 -> 31000 | H7: =+MACONS!H31 -> 0 | I7: =+MACONS!I31 -> 0 | J7: =+MACONS!J31 -> 4 | K7: =+MACONS!K31 -> 32000 | ... Q7: =+MACONS!Q31 -> 32000 | R7: =+SUM(Q7,O7,M7,K7,G7,E7,I7) -> 197500 | S7: =+MACONS!T31 -> 0 | T7: =+R7-S7 -> 197500
A8: 2 | B8: FERAILLEURS | C8: 7500 | D8: =+FERRAILLEURS!D31 -> 13 | E8: =+FERRAILLEURS!E31 -> 98500 | F8: =+FERRAILLEURS!F31 -> 12 | G8: =+FERRAILLEURS!G31 -> 91000 | H8: =+FERRAILLEURS!H31 -> 4 | I8: =+FERRAILLEURS!I31 -> 31000 | J8: =+FERRAILLEURS!J31 -> 13 | K8: =+FERRAILLEURS!K31 -> 98500 | ... Q8: =+FERRAILLEURS!Q31 -> 76000 | R8: =+SUM(Q8,O8,M8,K8,G8,E8,I8) -> 573250 | S8: =+FERRAILLEURS!T31 -> 0 | T8: =+R8-S8 -> 573250
A9: 3 | B9: COFFREURS | C9: 7500 | D9: =+COFFREURS!D30 -> 7 | E9: =+COFFREURS!E30 -> 55500 | F9: =+COFFREURS!F30 -> 8 | G9: =+COFFREURS!G30 -> 62000 | H9: =+COFFREURS!H30 -> 3 | I9: =+COFFREURS!I30 -> 24500 | J9: =+COFFREURS!J30 -> 8 | K9: =+COFFREURS!K30 -> 63000 | ... Q9: =+COFFREURS!Q30 -> 55500 | R9: =+SUM(Q9,O9,M9,K9,G9,E9,I9) -> 371500 | S9: =+COFFREURS!T30 -> 0 | T9: =+R9-S9 -> 371500
A10: 4 | B10: PLOMBIERS | C10: 7500 | D10: =+PLOMBIERS!D31 -> 4 | E10: =+PLOMBIERS!E31 -> 31000 | F10: =+PLOMBIERS!F31 -> 3 | G10: =+PLOMBIERS!G31 -> 22500 | H10: =+PLOMBIERS!H31 -> 0 | I10: =+PLOMBIERS!I31 -> 0 | J10: =+PLOMBIERS!J31 -> 0 | K10: =+PLOMBIERS!K31 -> 0 | ... Q10: =+PLOMBIERS!Q31 -> 0 | R10: =+SUM(Q10,O10,M10,K10,G10,E10,I10) -> 53500 | S10: =+PLOMBIERS!T31 -> 0 | T10: =+R10-S10 -> 53500
A11: 5 | B11: CONDUCTEUR D'ENGINS | C11: 10000 | D11: =+'CONDUCTEUR D''ENGINS'!D31 -> 0 | E11: =+'CONDUCTEUR D''ENGINS'!E31 -> 0 | F11: =+'CONDUCTEUR D''ENGINS'!F31 -> 0 | G11: =+'CONDUCTEUR D''ENGINS'!G31 -> 0 | H11: =+'CONDUCTEUR D''ENGINS'!H31 -> 0 | I11: =+'CONDUCTEUR D''ENGINS'!I31 -> 0 | J11: =+'CONDUCTEUR D''ENGINS'!J31 -> 0 | K11: =+'CONDUCTEUR D''ENGINS'!K31 -> 0 | ... Q11: =+'CONDUCTEUR D''ENGINS'!Q31 -> 0 | R11: =+SUM(Q11,O11,M11,K11,G11,E11,I11) -> 0 | S11: =+'CONDUCTEUR D''ENGINS'!T31 -> 0 | T11: =+R11-S11 -> 0
A12: 6 | B12: OPERATEURS BETONNIERES | C12: 7500 | D12: =+'OPERATEUR BETONNIERE'!D31 -> 2 | E12: =+'OPERATEUR BETONNIERE'!E31 -> 15000 | F12: =+'OPERATEUR BETONNIERE'!F31 -> 2 | G12: =+'OPERATEUR BETONNIERE'!G31 -> 15000 | H12: =+'OPERATEUR BETONNIERE'!H31 -> 0 | I12: =+'OPERATEUR BETONNIERE'!I31 -> 0 | J12: =+'OPERATEUR BETONNIERE'!J31 -> 1 | K12: =+'OPERATEUR BETONNIERE'!K31 -> 7500 | ... Q12: =+'OPERATEUR BETONNIERE'!Q31 -> 7500 | R12: =+SUM(Q12,O12,M12,K12,G12,E12,I12) -> 60000 | S12: =+'OPERATEUR BETONNIERE'!T31 -> 0 | T12: =+R12-S12 -> 60000
A13: 7 | B13: AIDES CHANTIER | C13: 4500 | D13: =+'AIDE CHANTIER'!D58 -> 23 | E13: =+'AIDE CHANTIER'!E58 -> 103500 | F13: =+'AIDE CHANTIER'!F58 -> 20 | G13: =+'AIDE CHANTIER'!G58 -> 90000 | H13: =+'AIDE CHANTIER'!H58 -> 0 | I13: =+'AIDE CHANTIER'!I58 -> 0 | J13: =+'AIDE CHANTIER'!J58 -> 22 | K13: =+'AIDE CHANTIER'!K58 -> 99000 | ... Q13: =+'AIDE CHANTIER'!Q58 -> 90000 | R13: =+SUM(Q13,O13,M13,K13,G13,E13,I13) -> 582750 | S13: =+'AIDE CHANTIER'!T58 -> 0 | T13: =+R13-S13 -> 582750
A14: 8 | B14: HEURES SUPPLEMENTAIRES | C14: 2500 | D14: =+'HEURES SUP'!D58 -> 0 | E14: =+'HEURES SUP'!E58 -> 0 | F14: =+'HEURES SUP'!F58 -> 0 | G14: =+'HEURES SUP'!G58 -> 9631.25 | H14: =+'HEURES SUP'!H58 -> 0 | I14: =+'HEURES SUP'!I58 -> 0 | J14: =+'HEURES SUP'!J58 -> 0 | K14: =+'HEURES SUP'!K58 -> 0 | ... Q14: =+'HEURES SUP'!Q58 -> 0 | R14: =+SUM(Q14,O14,M14,K14,G14,E14,I14) -> 9631.25 | S14: =+'HEURES SUP'!T58 -> 0 | T14: =+R14-S14 -> 9631.25
B16: TOTAL | E16: =SUM(E7:E15) -> 334500 | G16: =SUM(G7:G15) -> 321131.25 | I16: =SUM(I7:I15) -> 55500 | K16: =SUM(K7:K15) -> 300000 | M16: =SUM(M7:M15) -> 292500 | O16: =SUM(O7:O15) -> 283500 | Q16: =SUM(Q7:Q15) -> 261000 | R16: =SUM(R7:R15) -> 1848131.2 | S16: =SUM(S7:S15) -> 0 | T16: =SUM(T7:T15) -> 1848131.2
A18: N° | B18: DESIGNATION | C18: COUT UNITAIRE | D18: VENDREDI | F18: SAMEDI | J18: LUNDI | L18: MARDI | N18: MERCREDI | P18: JEUDI | R18: TOTAL | S18: =+S4 -> RETENUE EPI | T18: =+T4 -> NET A PAYER
D19: REND | E19: MONTANT | F19: REND | G19: MONTANT | J19: REND | K19: MONTANT | L19: REND | M19: MONTANT | N19: REND | O19: MONTANT | P19: REND | Q19: MONTANT
A20: PRESTATAIRES
A21: 1 | R21: =+SUM(Q21,O21,M21,K21,G21,E21,I21) -> 0 | T21: =+R21-S21 -> 0
A22: 2 | R22: =+SUM(Q22,O22,M22,K22,G22,E22,I22) -> 0 | T22: =+R22-S22 -> 0
A23: 3 | R23: =+SUM(Q23,O23,M23,K23,G23,E23,I23) -> 0 | T23: =+R23-S23 -> 0
A24: 4 | R24: =+SUM(Q24,O24,M24,K24,G24,E24,I24) -> 0 | T24: =+R24-S24 -> 0
A25: 5 | R25: =+SUM(Q25,O25,M25,K25,G25,E25,I25) -> 0 | T25: =+R25-S25 -> 0
B26: TOTAL | E26: =SUM(E21:E25) -> 0 | G26: =SUM(G21:G25) -> 0 | I26: =SUM(I21:I25) -> 0 | K26: =SUM(K21:K25) -> 0 | M26: =SUM(M21:M25) -> 0 | O26: =SUM(O21:O25) -> 0 | Q26: =SUM(Q21:Q25) -> 0 | R26: =SUM(R21:R25) -> 0 | S26: =SUM(S20:S25) -> 0 | T26: =+R26-S26 -> 0
A27: CHEF CHANTIER | O27: CONDUCTEUR DES TRAVAUX

Sheet MACONS
B3: FICHE D'EMARGEMENT DES MACONS / SEMAINE DU 03/07/2026 AU 09/07/2026
B5: S/N | C5: NOM ET PRENOMS | D5: VENDREDI | F5: SAMEDI | H5: DIMANCHE | J5: LUNDI | L5: MARDI | N5: MERCREDI | P5: JEUDI | R5: TOTAL | T5: RETENUE EPI | U5: NET A PAYER
D6: JR TRAVAILLE | E6: MT JOURNALIER | F6: JR TRAVAILLE | G6: MT JOURNALIER | H6: JR TRAVAILLE | I6: MT JOURNALIER | J6: JR TRAVAILLE | K6: MT JOURNALIER | L6: JR TRAVAILLE | M6: MT JOURNALIER | N6: JR TRAVAILLE | O6: MT JOURNALIER | P6: JR TRAVAILLE | Q6: MT JOURNALIER | R6: JR TRAVAILLE | S6: MONTANT
B7: 1 | C7: MASSIE ARSENE | D7: 1 | E7: 8500 | F7: 1 | G7: 8500 | J7: 1 | K7: 8500 | L7: 1 | M7: 8500 | N7: 1 | O7: 8500 | P7: 1 | Q7: 8500 | R7: =+SUM(P7,N7,L7,J7,H7,F7,D7) -> 6 | S7: =+SUM(E7,G7,I7,K7,M7,O7,Q7) -> 51000 | U7: =+S7-T7 -> 51000
B8: 2 | C8: GUEI HYPPOLITE | D8: 0 | E8: 0 | F8: 0 | G8: 0 | J8: 1 | K8: 8500 | L8: 1 | M8: 8500 | N8: 1 | O8: 8500 | P8: 1 | Q8: 8500 | R8: =+SUM(P8,N8,L8,J8,H8,F8,D8) -> 4 | S8: =+SUM(E8,G8,I8,K8,M8,O8,Q8) -> 34000 | U8: =+S8-T8 -> 34000
B9: 3 | C9: LOKOURI SIMPLICE | D9: 0 | E9: 0 | F9: 0 | G9: 0 | J9: 0 | K9: 0 | L9: 0 | M9: 0 | N9: 0 | O9: 0 | P9: 0 | Q9: 0 | R9: =+SUM(P9,N9,L9,J9,H9,F9,D9) -> 0 | S9: =+SUM(E9,G9,I9,K9,M9,O9,Q9) -> 0 | U9: =+S9-T9 -> 0
B10: 4 | C10: DIAKITE BOUYAGUI | D10: 1 | E10: 7500 | F10: 1 | G10: 7500 | J10: 1 | K10: 7500 | L10: 1 | M10: 7500 | N10: 1 | O10: 7500 | P10: 1 | Q10: 7500 | R10: =+SUM(P10,N10,L10,J10,H10,F10,D10) -> 6 | S10: =+SUM(E10,G10,I10,K10,M10,O10,Q10) -> 45000 | U10: =+S10-T10 -> 45000
B11: 5 | C11: KOULAEOULOU ROLAND | D11: 0 | E11: 0 | F11: 0 | G11: 0 | J11: 0 | K11: 0 | L11: 0 | M11: 0 | N11: 0 | O11: 0 | P11: 0 | Q11: 0 | R11: =+SUM(P11,N11,L11,J11,H11,F11,D11) -> 0 | S11: =+SUM(E11,G11,I11,K11,M11,O11,Q11) -> 0 | U11: =+S11-T11 -> 0
B12: 6 | C12: YANOU ALAIN | D12: 0 | E12: 0 | F12: 0 | G12: 0 | J12: 0 | K12: 0 | L12: 0 | M12: 0 | N12: 0 | O12: 0 | P12: 0 | Q12: 0 | R12: =+SUM(P12,N12,L12,J12,H12,F12,D12) -> 0 | S12: =+SUM(E12,G12,I12,K12,M12,O12,Q12) -> 0 | U12: =+S12-T12 -> 0
B13: 7 | C13: BLEDI SABIN | D13: 1 | E13: 7500 | F13: 1 | G13: 7500 | J13: 1 | K13: 7500 | L13: 1 | M13: 7500 | N13: 0 | O13: 0 | P13: 0 | Q13: 0 | R13: =+SUM(P13,N13,L13,J13,H13,F13,D13) -> 4 | S13: =+SUM(E13,G13,I13,K13,M13,O13,Q13) -> 30000 | U13: =+S13-T13 -> 30000
B14: 8 | C14: OULA BOLE PARTERNE | D14: 0 | E14: 0 | F14: 0 | G14: 0 | J14: 0 | K14: 0 | L14: 0 | M14: 0 | N14: 0 | O14: 0 | P14: 0 | Q14: 0 | R14: =+SUM(P14,N14,L14,J14,H14,F14,D14) -> 0 | S14: =+SUM(E14,G14,I14,K14,M14,O14,Q14) -> 0 | U14: =+S14-T14 -> 0
B15: 9 | C15: BOUMOU CLEMENT | D15: 1 | E15: 7500 | F15: 1 | G15: 7500 | J15: 0 | K15: 0 | L15: 1 | M15: 7500 | N15: 1 | O15: 7500 | P15: 1 | Q15: 7500 | R15: =+SUM(P15,N15,L15,J15,H15,F15,D15) -> 5 | S15: =+SUM(E15,G15,I15,K15,M15,O15,Q15) -> 37500 | U15: =+S15-T15 -> 37500
B16: 10 | R16: =+SUM(P16,N16,L16,J16,H16,F16,D16) -> 0 | S16: =+SUM(E16,G16,I16,K16,M16,O16,Q16) -> 0 | U16: =+S16-T16 -> 0
B17: 11 | R17: =+SUM(P17,N17,L17,J17,H17,F17,D17) -> 0 | S17: =+SUM(E17,G17,I17,K17,M17,O17,Q17) -> 0 | U17: =+S17-T17 -> 0
B18: 12 | R18: =+SUM(P18,N18,L18,J18,H18,F18,D18) -> 0 | S18: =+SUM(E18,G18,I18,K18,M18,O18,Q18) -> 0 | U18: =+S18-T18 -> 0
B19: 13 | R19: =+SUM(P19,N19,L19,J19,H19,F19,D19) -> 0 | S19: =+SUM(E19,G19,I19,K19,M19,O19,Q19) -> 0 | U19: =+S19-T19 -> 0
B20: 14 | R20: =+SUM(P20,N20,L20,J20,H20,F20,D20) -> 0 | S20: =+SUM(E20,G20,I20,K20,M20,O20,Q20) -> 0 | U20: =+S20-T20 -> 0
B21: 15 | R21: =+SUM(P21,N21,L21,J21,H21,F21,D21) -> 0 | S21: =+SUM(E21,G21,I21,K21,M21,O21,Q21) -> 0 | U21: =+S21-T21 -> 0
B22: 16 | R22: =+SUM(P22,N22,L22,J22,H22,F22,D22) -> 0 | S22: =+SUM(E22,G22,I22,K22,M22,O22,Q22) -> 0 | U22: =+S22-T22 -> 0
B23: 17 | R23: =+SUM(P23,N23,L23,J23,H23,F23,D23) -> 0 | S23: =+SUM(E23,G23,I23,K23,M23,O23,Q23) -> 0 | U23: =+S23-T23 -> 0
B24: 18 | R24: =+SUM(P24,N24,L24,J24,H24,F24,D24) -> 0 | S24: =+SUM(E24,G24,I24,K24,M24,O24,Q24) -> 0 | U24: =+S24-T24 -> 0
B25: 19 | R25: =+SUM(P25,N25,L25,J25,H25,F25,D25) -> 0 | S25: =+SUM(E25,G25,I25,K25,M25,O25,Q25) -> 0 | U25: =+S25-T25 -> 0
B26: 20 | R26: =+SUM(P26,N26,L26,J26,H26,F26,D26) -> 0 | S26: =+SUM(E26,G26,I26,K26,M26,O26,Q26) -> 0 | U26: =+S26-T26 -> 0
B27: 21 | R27: =+SUM(P27,N27,L27,J27,H27,F27,D27) -> 0 | S27: =+SUM(E27,G27,I27,K27,M27,O27,Q27) -> 0 | U27: =+S27-T27 -> 0
... B30: 24 | R30: =+SUM(P30,N30,L30,J30,H30,F30,D30) -> 0 | S30: =+SUM(E30,G30,I30,K30,M30,O30,Q30) -> 0 | U30: =+S30-T30 -> 0
B31: Total | D31: =SUM(D7:D30) -> 4 | E31: =SUM(E7:E30) -> 31000 | F31: =SUM(F7:F30) -> 4 | G31: =SUM(G7:G30) -> 31000 | H31: =SUM(H7:H30) -> 0 | I31: =SUM(I7:I30) -> 0 | J31: =SUM(J7:J30) -> 4 | K31: =SUM(K7:K30) -> 32000 | ... Q31: =SUM(Q7:Q30) -> 32000 | R31: =+SUM(P31,N31,L31,J31,H31,F31,D31) -> 25 | S31: =+SUM(E31,G31,I31,K31,M31,O31,Q31) -> 197500 | T31: =SUBTOTAL(109,MACONS!$T$7:$T$30) -> 0 | U31: =SUBTOTAL(109,MACONS!$U$7:$U$30) -> 197500
P33: Check | R33: =+MACONS!$R$31-SUM('SUIVI HEBDOMADAIRE PAIE'!D7,'SUIVI HEBDOMADAIRE PAIE'!F7,'SUIVI HEBDOMADAIRE PAIE'!H7,'SUIVI HEBDOMADAIRE PAIE'!J7,'SUIVI HEBDOMADAIRE PAIE'!L7,'SUIVI HEBDOMADAIRE PAIE'!N7,'SUIVI HEBDOMADAIRE PAIE'!P7) -> 0

Sheet FERRAILLEURS
B3: FICHE D'EMARGEMENT DES FERRAILLEURS / SEMAINE DU 03/07/2026 AU 09/07/2026
B5: S/N | C5: NOM ET PRENOMS | D5: VENDREDI | F5: SAMEDI | H5: DIMANCHE | J5: LUNDI | L5: MARDI | N5: MERCREDI | P5: JEUDI | R5: TOTAL | T5: RETENUE EPI | U5: NET A PAYER
D6: JR TRAVAILLE | E6: MT JOURNALIER | F6: JR TRAVAILLE | G6: MT JOURNALIER | H6: JR TRAVAILLE | I6: MT JOURNALIER | J6: JR TRAVAILLE | K6: MT JOURNALIER | L6: JR TRAVAILLE | M6: MT JOURNALIER | N6: JR TRAVAILLE | O6: MT JOURNALIER | P6: JR TRAVAILLE | Q6: MT JOURNALIER | R6: JR TRAVAILLE | S6: MONTANT
B7: 1 | C7: DJEHI BI CLEMENT | D7: 1 | E7: 7500 | F7: 1 | G7: 7500 | J7: 1 | K7: 7500 | L7: 1 | M7: 7500 | N7: 1 | O7: 7500 | P7: 1 | Q7: 7500 | R7: =+SUM(P7,N7,L7,J7,H7,F7,D7) -> 6 | S7: =+SUM(E7,G7,I7,K7,M7,O7,Q7) -> 45000 | U7: =+S7-T7 -> 45000
B8: 2 | C8: IRIE LEZIE NOEL | D8: 1 | E8: 7500 | F8: 1 | G8: 7500 | H8: 1 | I8: 7500 | J8: 1 | K8: 7500 | L8: 1 | M8: 7500 | N8: 1 | O8: 7500 | P8: 1 | Q8: 7500 | R8: =+SUM(P8,N8,L8,J8,H8,F8,D8) -> 7 | S8: =+SUM(E8,G8,I8,K8,M8,O8,Q8) -> 52500 | U8: =+S8-T8 -> 52500
B9: 3 | C9: ZORO BI ZIBO | D9: 1 | E9: 7500 | F9: 0 | G9: 0 | J9: 1 | K9: 7500 | L9: 1 | M9: 7500 | N9: 1 | O9: 7500 | P9: 1 | Q9: 7500 | R9: =+SUM(P9,N9,L9,J9,H9,F9,D9) -> 5 | S9: =+SUM(E9,G9,I9,K9,M9,O9,Q9) -> 37500 | U9: =+S9-T9 -> 37500
B10: 4 | C10: DIE BLE ALBAN | D10: 1 | E10: 7500 | F10: 1 | G10: 7500 | H10: 1 | I10: 7500 | J10: 1 | K10: 7500 | L10: 1 | M10: 7500 | N10: 1 | O10: 7500 | P10: 1 | Q10: 7500 | R10: =+SUM(P10,N10,L10,J10,H10,F10,D10) -> 7 | S10: =+SUM(E10,G10,I10,K10,M10,O10,Q10) -> 52500 | U10: =+S10-T10 -> 52500
B11: 5 | C11: KOUAI BI BAKI | D11: 0 | E11: 0 | F11: 0 | G11: 0 | J11: 0 | K11: 0 | L11: 0 | M11: 0 | N11: 0 | O11: 0 | P11: 0 | Q11: 0 | R11: =+SUM(P11,N11,L11,J11,H11,F11,D11) -> 0 | S11: =+SUM(E11,G11,I11,K11,M11,O11,Q11) -> 0 | U11: =+S11-T11 -> 0
B12: 6 | C12: GOURIA KELEWIN ELYSEE | D12: 1 | E12: 8500 | F12: 1 | G12: 8500 | H12: 1 | I12: 8500 | J12: 1 | K12: 8500 | L12: 1 | M12: 8500 | N12: 1 | O12: 8500 | P12: 1 | Q12: 8500 | R12: =+SUM(P12,N12,L12,J12,H12,F12,D12) -> 7 | S12: =+SUM(E12,G12,I12,K12,M12,O12,Q12) -> 59500 | U12: =+S12-T12 -> 59500
B13: 7 | C13: TOH BI TRA DIEUDONNE | D13: 1 | E13: 7500 | F13: 1 | G13: 7500 | J13: 1 | K13: 7500 | L13: 0 | M13: 0 | N13: 0 | O13: 0 | P13: 0 | Q13: 0 | R13: =+SUM(P13,N13,L13,J13,H13,F13,D13) -> 3 | S13: =+SUM(E13,G13,I13,K13,M13,O13,Q13) -> 22500 | U13: =+S13-T13 -> 22500
B14: 8 | C14: KONAN KOUASSI MICHEL | D14: 1 | E14: 7500 | F14: 1 | G14: 7500 | J14: 1 | K14: 7500 | L14: 1 | M14: 7500 | N14: 1 | O14: 7500 | P14: 1 | Q14: 7500 | R14: =+SUM(P14,N14,L14,J14,H14,F14,D14) -> 6 | S14: =+SUM(E14,G14,I14,K14,M14,O14,Q14) -> 45000 | U14: =+S14-T14 -> 45000
B15: 9 | C15: LIZIE BI IRIE YANNICK | D15: 1 | E15: 7500 | F15: 1 | G15: 7500 | J15: 1 | K15: 7500 | L15: 1 | M15: 7500 | N15: 1 | O15: 7500 | P15: 1 | Q15: 7500 | R15: =+SUM(P15,N15,L15,J15,H15,F15,D15) -> 6 | S15: =+SUM(E15,G15,I15,K15,M15,O15,Q15) -> 45000 | U15: =+S15-T15 -> 45000
B16: 10 | C16: TOKPA CHERIF | D16: 1 | E16: 7500 | F16: 1 | G16: 7500 | J16: 1 | K16: 7500 | L16: 1 | M16: 7500 | N16: 1 | O16: 7500 | P16: 1 | Q16: 7500 | R16: =+SUM(P16,N16,L16,J16,H16,F16,D16) -> 6 | S16: =+SUM(E16,G16,I16,K16,M16,O16,Q16) -> 45000 | U16: =+S16-T16 -> 45000
B17: 11 | C17: GONLOUA JOSUE | D17: 1 | E17: 7500 | F17: 1 | G17: 7500 | J17: 1 | K17: 7500 | L17: 1 | M17: 7500 | N17: 1 | O17: 7500 | P17: 0 | Q17: 0 | R17: =+SUM(P17,N17,L17,J17,H17,F17,D17) -> 5 | S17: =+SUM(E17,G17,I17,K17,M17,O17,Q17) -> 37500 | U17: =+S17-T17 -> 37500
B18: 12 | C18: DOUBI BI DOUBI ROLLY | D18: 1 | E18: 7500 | F18: 1 | G18: 7500 | J18: 1 | K18: 7500 | L18: 1 | M18: 7500 | N18: 1 | O18: 7500 | P18: 1 | Q18: 7500 | R18: =+SUM(P18,N18,L18,J18,H18,F18,D18) -> 6 | S18: =+SUM(E18,G18,I18,K18,M18,O18,Q18) -> 45000 | U18: =+S18-T18 -> 45000
B19: 13 | C19: BOUO JOSE | D19: 1 | E19: 7500 | F19: 1 | G19: 7500 | J19: 1 | K19: 7500 | L19: 1 | M19: 7500 | N19: 0.5 | O19: 3750 | P19: 0 | Q19: 0 | R19: =+SUM(P19,N19,L19,J19,H19,F19,D19) -> 4.5 | S19: =+SUM(E19,G19,I19,K19,M19,O19,Q19) -> 33750 | U19: =+S19-T19 -> 33750
B20: 14 | C20: GOUESSE OSCAR | D20: 1 | E20: 7500 | F20: 1 | G20: 7500 | H20: 1 | I20: 7500 | J20: 1 | K20: 7500 | L20: 1 | M20: 7500 | N20: 1 | O20: 7500 | P20: 1 | Q20: 7500 | R20: =+SUM(P20,N20,L20,J20,H20,F20,D20) -> 7 | S20: =+SUM(E20,G20,I20,K20,M20,O20,Q20) -> 52500 | U20: =+S20-T20 -> 52500
B21: 15 | R21: =+SUM(P21,N21,L21,J21,H21,F21,D21) -> 0 | S21: =+SUM(E21,G21,I21,K21,M21,O21,Q21) -> 0 | U21: =+S21-T21 -> 0
B22: 16 | R22: =+SUM(P22,N22,L22,J22,H22,F22,D22) -> 0 | S22: =+SUM(E22,G22,I22,K22,M22,O22,Q22) -> 0 | U22: =+S22-T22 -> 0
B23: 17 | R23: =+SUM(P23,N23,L23,J23,H23,F23,D23) -> 0 | S23: =+SUM(E23,G23,I23,K23,M23,O23,Q23) -> 0 | U23: =+S23-T23 -> 0
B24: 18 | R24: =+SUM(P24,N24,L24,J24,H24,F24,D24) -> 0 | S24: =+SUM(E24,G24,I24,K24,M24,O24,Q24) -> 0 | U24: =+S24-T24 -> 0
B25: 19 | R25: =+SUM(P25,N25,L25,J25,H25,F25,D25) -> 0 | S25: =+SUM(E25,G25,I25,K25,M25,O25,Q25) -> 0 | U25: =+S25-T25 -> 0
B26: 20 | R26: =+SUM(P26,N26,L26,J26,H26,F26,D26) -> 0 | S26: =+SUM(E26,G26,I26,K26,M26,O26,Q26) -> 0 | U26: =+S26-T26 -> 0
B27: 21 | R27: =+SUM(P27,N27,L27,J27,H27,F27,D27) -> 0 | S27: =+SUM(E27,G27,I27,K27,M27,O27,Q27) -> 0 | U27: =+S27-T27 -> 0
B28: 22 | R28: =+SUM(P28,N28,L28,J28,H28,F28,D28) -> 0 | S28: =+SUM(E28,G28,I28,K28,M28,O28,Q28) -> 0 | U28: =+S28-T28 -> 0
B29: 23 | R29: =+SUM(P29,N29,L29,J29,H29,F29,D29) -> 0 | S29: =+SUM(E29,G29,I29,K29,M29,O29,Q29) -> 0 | U29: =+S29-T29 -> 0
B30: 24 | R30: =+SUM(P30,N30,L30,J30,H30,F30,D30) -> 0 | S30: =+SUM(E30,G30,I30,K30,M30,O30,Q30) -> 0 | U30: =+S30-T30 -> 0
B31: Total | D31: =SUM(D7:D30) -> 13 | E31: =SUM(E7:E30) -> 98500 | F31: =SUM(F7:F30) -> 12 | G31: =SUM(G7:G30) -> 91000 | H31: =SUM(H7:H30) -> 4 | I31: =SUM(I7:I30) -> 31000 | J31: =SUM(J7:J30) -> 13 | K31: =SUM(K7:K30) -> 98500 | ... Q31: =SUM(Q7:Q30) -> 76000 | R31: =+SUM(P31,N31,L31,J31,H31,F31,D31) -> 75.5 | S31: =+SUM(E31,G31,I31,K31,M31,O31,Q31) -> 573250 | T31: =SUBTOTAL(109,MACONS!$T$7:$T$30) -> 0 | U31: =SUBTOTAL(109,MACONS!$U$7:$U$30) -> 197500
P33: Check | R33: =+MACONS!$R$31-SUM('SUIVI HEBDOMADAIRE PAIE'!D7,'SUIVI HEBDOMADAIRE PAIE'!F7,'SUIVI HEBDOMADAIRE PAIE'!H7,'SUIVI HEBDOMADAIRE PAIE'!J7,'SUIVI HEBDOMADAIRE PAIE'!L7,'SUIVI HEBDOMADAIRE PAIE'!N7,'SUIVI HEBDOMADAIRE PAIE'!P7) -> 0

Sheet COFFREURS
B3: FICHE D'EMARGEMENT DES COFFREURS / SEMAINE DU 03/07/2026 AU 09/07/2026
B5: S/N | C5: NOM ET PRENOMS | D5: VENDREDI | F5: SAMEDI | H5: DIMANCHE | J5: LUNDI | L5: MARDI | N5: MERCREDI | P5: JEUDI | R5: TOTAL | T5: RETENUE EPI | U5: NET A PAYER
D6: JR TRAVAILLE | E6: MT JOURNALIER | F6: JR TRAVAILLE | G6: MT JOURNALIER | H6: JR TRAVAILLE | I6: MT JOURNALIER | J6: JR TRAVAILLE | K6: MT JOURNALIER | L6: JR TRAVAILLE | M6: MT JOURNALIER | N6: JR TRAVAILLE | O6: MT JOURNALIER | P6: JR TRAVAILLE | Q6: MT JOURNALIER | R6: JR TRAVAILLE | S6: MONTANT
B7: 1 | C7: BLE SEDET ANICET | D7: 1 | E7: 8500 | F7: 0 | G7: 0 | H7: 1 | I7: 8500 | J7: 1 | K7: 8500 | L7: 1 | M7: 8500 | N7: 1 | O7: 8500 | P7: 1 | Q7: 8500 | R7: =+SUM(P7,N7,L7,J7,H7,F7,D7) -> 6 | S7: =+SUM(E7,G7,I7,K7,M7,O7,Q7) -> 51000 | U7: =+S7-T7 -> 51000
B8: 2 | C8: BLE SEDET ARMEL | D8: 1 | E8: 8500 | F8: 1 | G8: 8500 | H8: 1 | I8: 8500 | J8: 1 | K8: 8500 | L8: 1 | M8: 8500 | N8: 1 | O8: 8500 | P8: 1 | Q8: 8500 | R8: =+SUM(P8,N8,L8,J8,H8,F8,D8) -> 7 | S8: =+SUM(E8,G8,I8,K8,M8,O8,Q8) -> 59500 | U8: =+S8-T8 -> 59500
B9: 3 | C9: KONE ROMEO | D9: 1 | E9: 7500 | F9: 1 | G9: 7500 | J9: 1 | K9: 7500 | L9: 1 | M9: 7500 | N9: 1 | O9: 7500 | P9: 1 | Q9: 7500 | R9: =+SUM(P9,N9,L9,J9,H9,F9,D9) -> 6 | S9: =+SUM(E9,G9,I9,K9,M9,O9,Q9) -> 45000 | U9: =+S9-T9 -> 45000
B10: 4 | C10: ZAHIBO OBRE MARC | D10: 1 | E10: 7500 | F10: 1 | G10: 7500 | J10: 1 | K10: 7500 | L10: 0 | M10: 0 | N10: 0 | O10: 0 | P10: 0 | Q10: 0 | R10: =+SUM(P10,N10,L10,J10,H10,F10,D10) -> 3 | S10: =+SUM(E10,G10,I10,K10,M10,O10,Q10) -> 22500 | U10: =+S10-T10 -> 22500
B11: 5 | C11: DIOMANDE FRANCK | D11: 0 | E11: 0 | F11: 1 | G11: 7500 | J11: 1 | K11: 7500 | L11: 1 | M11: 7500 | N11: 1 | O11: 7500 | P11: 1 | Q11: 7500 | R11: =+SUM(P11,N11,L11,J11,H11,F11,D11) -> 5 | S11: =+SUM(E11,G11,I11,K11,M11,O11,Q11) -> 37500 | U11: =+S11-T11 -> 37500
B12: 6 | C12: KOUADIO JEAN PRIVA | D12: 1 | E12: 8500 | F12: 1 | G12: 8500 | J12: 1 | K12: 8500 | L12: 1 | M12: 8500 | N12: 1 | O12: 8500 | P12: 1 | Q12: 8500 | R12: =+SUM(P12,N12,L12,J12,H12,F12,D12) -> 6 | S12: =+SUM(E12,G12,I12,K12,M12,O12,Q12) -> 51000 | U12: =+S12-T12 -> 51000
B13: 7 | C13: YATTE BORIS | D13: 1 | E13: 7500 | F13: 1 | G13: 7500 | J13: 0 | K13: 0 | L13: 0 | M13: 0 | N13: 0 | P13: 0 | Q13: 0 | R13: =+SUM(P13,N13,L13,J13,H13,F13,D13) -> 2 | S13: =+SUM(E13,G13,I13,K13,M13,O13,Q13) -> 15000 | U13: =+S13-T13 -> 15000
B14: 8 | C14: GOGBEU EUDES | D14: 1 | E14: 7500 | F14: 1 | G14: 7500 | H14: 1 | I14: 7500 | J14: 1 | K14: 7500 | L14: 1 | M14: 7500 | N14: 1 | O14: 7500 | P14: 1 | Q14: 7500 | R14: =+SUM(P14,N14,L14,J14,H14,F14,D14) -> 7 | S14: =+SUM(E14,G14,I14,K14,M14,O14,Q14) -> 52500 | U14: =+S14-T14 -> 52500
B15: 9 | C15: OULAI ARNAUD | D15: 0 | E15: 0 | F15: 1 | G15: 7500 | J15: 1 | K15: 7500 | L15: 1 | M15: 7500 | N15: 1 | O15: 7500 | P15: 1 | Q15: 7500 | R15: =+SUM(P15,N15,L15,J15,H15,F15,D15) -> 5 | S15: =+SUM(E15,G15,I15,K15,M15,O15,Q15) -> 37500 | U15: =+S15-T15 -> 37500
B16: 10 | R16: =+SUM(P16,N16,L16,J16,H16,F16,D16) -> 0 | S16: =+SUM(E16,G16,I16,K16,M16,O16,Q16) -> 0 | U16: =+S16-T16 -> 0
B17: 11 | R17: =+SUM(P17,N17,L17,J17,H17,F17,D17) -> 0 | S17: =+SUM(E17,G17,I17,K17,M17,O17,Q17) -> 0 | U17: =+S17-T17 -> 0
B18: 12 | R18: =+SUM(P18,N18,L18,J18,H18,F18,D18) -> 0 | S18: =+SUM(E18,G18,I18,K18,M18,O18,Q18) -> 0 | U18: =+S18-T18 -> 0
B19: 13 | R19: =+SUM(P19,N19,L19,J19,H19,F19,D19) -> 0 | S19: =+SUM(E19,G19,I19,K19,M19,O19,Q19) -> 0 | U19: =+S19-T19 -> 0
B20: 14 | R20: =+SUM(P20,N20,L20,J20,H20,F20,D20) -> 0 | S20: =+SUM(E20,G20,I20,K20,M20,O20,Q20) -> 0 | U20: =+S20-T20 -> 0
B21: 15 | R21: =+SUM(P21,N21,L21,J21,H21,F21,D21) -> 0 | S21: =+SUM(E21,G21,I21,K21,M21,O21,Q21) -> 0 | U21: =+S21-T21 -> 0
B22: 16 | R22: =+SUM(P22,N22,L22,J22,H22,F22,D22) -> 0 | S22: =+SUM(E22,G22,I22,K22,M22,O22,Q22) -> 0 | U22: =+S22-T22 -> 0
B23: 17 | R23: =+SUM(P23,N23,L23,J23,H23,F23,D23) -> 0 | S23: =+SUM(E23,G23,I23,K23,M23,O23,Q23) -> 0 | U23: =+S23-T23 -> 0
B24: 18 | R24: =+SUM(P24,N24,L24,J24,H24,F24,D24) -> 0 | S24: =+SUM(E24,G24,I24,K24,M24,O24,Q24) -> 0 | U24: =+S24-T24 -> 0
B25: 19 | R25: =+SUM(P25,N25,L25,J25,H25,F25,D25) -> 0 | S25: =+SUM(E25,G25,I25,K25,M25,O25,Q25) -> 0 | U25: =+S25-T25 -> 0
B26: 20 | R26: =+SUM(P26,N26,L26,J26,H26,F26,D26) -> 0 | S26: =+SUM(E26,G26,I26,K26,M26,O26,Q26) -> 0 | U26: =+S26-T26 -> 0
B27: 21 | R27: =+SUM(P27,N27,L27,J27,H27,F27,D27) -> 0 | S27: =+SUM(E27,G27,I27,K27,M27,O27,Q27) -> 0 | U27: =+S27-T27 -> 0
... B29: 23 | R29: =+SUM(P29,N29,L29,J29,H29,F29,D29) -> 0 | S29: =+SUM(E29,G29,I29,K29,M29,O29,Q29) -> 0 | U29: =+S29-T29 -> 0
B30: Total | D30: =SUM(D7:D29) -> 7 | E30: =SUM(E7:E29) -> 55500 | F30: =SUM(F7:F29) -> 8 | G30: =SUM(G7:G29) -> 62000 | H30: =SUM(H7:H29) -> 3 | I30: =SUM(I7:I29) -> 24500 | J30: =SUM(J7:J29) -> 8 | K30: =SUM(K7:K29) -> 63000 | ... Q30: =SUM(Q7:Q29) -> 55500 | R30: =+SUM(P30,N30,L30,J30,H30,F30,D30) -> 47 | S30: =+SUM(E30,G30,I30,K30,M30,O30,Q30) -> 371500 | T30: =SUBTOTAL(109,MACONS!$T$7:$T$30) -> 0 | U30: =SUBTOTAL(109,MACONS!$U$7:$U$30) -> 197500
P32: Check | R32: =+MACONS!$R$31-SUM('SUIVI HEBDOMADAIRE PAIE'!D7,'SUIVI HEBDOMADAIRE PAIE'!F7,'SUIVI HEBDOMADAIRE PAIE'!H7,'SUIVI HEBDOMADAIRE PAIE'!J7,'SUIVI HEBDOMADAIRE PAIE'!L7,'SUIVI HEBDOMADAIRE PAIE'!N7,'SUIVI HEBDOMADAIRE PAIE'!P7) -> 0

Sheet PLOMBIERS
B3: FICHE D'EMARGEMENT DES POMBLIERS / SEMAINE DU 03/07/2026 AU 09/07/2026
B5: S/N | C5: NOM ET PRENOMS | D5: VENDREDI | F5: SAMEDI | H5: DIMANCHE | J5: LUNDI | L5: MARDI | N5: MERCREDI | P5: JEUDI | R5: TOTAL | T5: RETENUE EPI | U5: NET A PAYER
D6: JR TRAVAILLE | E6: MT JOURNALIER | F6: JR TRAVAILLE | G6: MT JOURNALIER | H6: JR TRAVAILLE | I6: MT JOURNALIER | J6: JR TRAVAILLE | K6: MT JOURNALIER | L6: JR TRAVAILLE | M6: MT JOURNALIER | N6: JR TRAVAILLE | O6: MT JOURNALIER | P6: JR TRAVAILLE | Q6: MT JOURNALIER | R6: JR TRAVAILLE | S6: MONTANT
B7: 1 | C7: AMANI PIERRE | D7: 1 | E7: 8500 | F7: 0 | G7: 0 | J7: 0 | K7: 0 | L7: 0 | M7: 0 | N7: 0 | O7: 0 | P7: 0 | Q7: 0 | R7: =+SUM(P7,N7,L7,J7,H7,F7,D7) -> 1 | S7: =+SUM(E7,G7,I7,K7,M7,O7,Q7) -> 8500 | U7: =+S7-T7 -> 8500
B8: 2 | C8: AHIRE KOUASSI | D8: 1 | E8: 7500 | F8: 1 | G8: 7500 | J8: 0 | K8: 0 | L8: 0 | M8: 0 | N8: 0 | O8: 0 | P8: 0 | Q8: 0 | R8: =+SUM(P8,N8,L8,J8,H8,F8,D8) -> 2 | S8: =+SUM(E8,G8,I8,K8,M8,O8,Q8) -> 15000 | U8: =+S8-T8 -> 15000
B9: 3 | C9: KOUASSI ISIDORE | D9: 1 | E9: 7500 | F9: 1 | G9: 7500 | J9: 0 | K9: 0 | L9: 0 | M9: 0 | N9: 0 | O9: 0 | P9: 0 | Q9: 0 | R9: =+SUM(P9,N9,L9,J9,H9,F9,D9) -> 2 | S9: =+SUM(E9,G9,I9,K9,M9,O9,Q9) -> 15000 | U9: =+S9-T9 -> 15000
B10: 4 | C10: OUSSOU KONAN MARIUS | D10: 1 | E10: 7500 | F10: 1 | G10: 7500 | J10: 0 | K10: 0 | L10: 0 | M10: 0 | N10: 0 | O10: 0 | P10: 0 | Q10: 0 | R10: =+SUM(P10,N10,L10,J10,H10,F10,D10) -> 2 | S10: =+SUM(E10,G10,I10,K10,M10,O10,Q10) -> 15000 | U10: =+S10-T10 -> 15000
B11: 5 | R11: =+SUM(P11,N11,L11,J11,H11,F11,D11) -> 0 | S11: =+SUM(E11,G11,I11,K11,M11,O11,Q11) -> 0 | U11: =+S11-T11 -> 0
B12: 6 | R12: =+SUM(P12,N12,L12,J12,H12,F12,D12) -> 0 | S12: =+SUM(E12,G12,I12,K12,M12,O12,Q12) -> 0 | U12: =+S12-T12 -> 0
B13: 7 | R13: =+SUM(P13,N13,L13,J13,H13,F13,D13) -> 0 | S13: =+SUM(E13,G13,I13,K13,M13,O13,Q13) -> 0 | U13: =+S13-T13 -> 0
B14: 8 | R14: =+SUM(P14,N14,L14,J14,H14,F14,D14) -> 0 | S14: =+SUM(E14,G14,I14,K14,M14,O14,Q14) -> 0 | U14: =+S14-T14 -> 0
B15: 9 | R15: =+SUM(P15,N15,L15,J15,H15,F15,D15) -> 0 | S15: =+SUM(E15,G15,I15,K15,M15,O15,Q15) -> 0 | U15: =+S15-T15 -> 0
B16: 10 | R16: =+SUM(P16,N16,L16,J16,H16,F16,D16) -> 0 | S16: =+SUM(E16,G16,I16,K16,M16,O16,Q16) -> 0 | U16: =+S16-T16 -> 0
B17: 11 | R17: =+SUM(P17,N17,L17,J17,H17,F17,D17) -> 0 | S17: =+SUM(E17,G17,I17,K17,M17,O17,Q17) -> 0 | U17: =+S17-T17 -> 0
B18: 12 | R18: =+SUM(P18,N18,L18,J18,H18,F18,D18) -> 0 | S18: =+SUM(E18,G18,I18,K18,M18,O18,Q18) -> 0 | U18: =+S18-T18 -> 0
B19: 13 | R19: =+SUM(P19,N19,L19,J19,H19,F19,D19) -> 0 | S19: =+SUM(E19,G19,I19,K19,M19,O19,Q19) -> 0 | U19: =+S19-T19 -> 0
B20: 14 | R20: =+SUM(P20,N20,L20,J20,H20,F20,D20) -> 0 | S20: =+SUM(E20,G20,I20,K20,M20,O20,Q20) -> 0 | U20: =+S20-T20 -> 0
B21: 15 | R21: =+SUM(P21,N21,L21,J21,H21,F21,D21) -> 0 | S21: =+SUM(E21,G21,I21,K21,M21,O21,Q21) -> 0 | U21: =+S21-T21 -> 0
B22: 16 | R22: =+SUM(P22,N22,L22,J22,H22,F22,D22) -> 0 | S22: =+SUM(E22,G22,I22,K22,M22,O22,Q22) -> 0 | U22: =+S22-T22 -> 0
... B30: 24 | R30: =+SUM(P30,N30,L30,J30,H30,F30,D30) -> 0 | S30: =+SUM(E30,G30,I30,K30,M30,O30,Q30) -> 0 | U30: =+S30-T30 -> 0
B31: Total | D31: =SUM(D7:D30) -> 4 | E31: =SUM(E7:E30) -> 31000 | F31: =SUM(F7:F30) -> 3 | G31: =SUM(G7:G30) -> 22500 | H31: =SUM(H7:H30) -> 0 | I31: =SUM(I7:I30) -> 0 | J31: =SUM(J7:J30) -> 0 | K31: =SUM(K7:K30) -> 0 | ... Q31: =SUM(Q7:Q30) -> 0 | R31: =+SUM(P31,N31,L31,J31,H31,F31,D31) -> 7 | S31: =+SUM(E31,G31,I31,K31,M31,O31,Q31) -> 53500 | T31: =SUBTOTAL(109,MACONS!$T$7:$T$30) -> 0 | U31: =SUBTOTAL(109,MACONS!$U$7:$U$30) -> 197500
P33: Check | R33: =+MACONS!$R$31-SUM('SUIVI HEBDOMADAIRE PAIE'!D7,'SUIVI HEBDOMADAIRE PAIE'!F7,'SUIVI HEBDOMADAIRE PAIE'!H7,'SUIVI HEBDOMADAIRE PAIE'!J7,'SUIVI HEBDOMADAIRE PAIE'!L7,'SUIVI HEBDOMADAIRE PAIE'!N7,'SUIVI HEBDOMADAIRE PAIE'!P7) -> 0

Sheet CONDUCTEUR D'ENGINS
B3: FICHE D'EMARGEMENT DES CONDUCTEURS D'ENGINS / SEMAINE DU 03/07/2026 AU 09/07/2026
B5: S/N | C5: NOM ET PRENOMS | D5: VENDREDI | F5: SAMEDI | H5: DIMANCHE | J5: LUNDI | L5: MARDI | N5: MERCREDI | P5: JEUDI | R5: TOTAL | T5: RETENUE EPI | U5: NET A PAYER
D6: JR TRAVAILLE | E6: MT JOURNALIER | F6: JR TRAVAILLE | G6: MT JOURNALIER | H6: JR TRAVAILLE | I6: MT JOURNALIER | J6: JR TRAVAILLE | K6: MT JOURNALIER | L6: JR TRAVAILLE | M6: MT JOURNALIER | N6: JR TRAVAILLE | O6: MT JOURNALIER | P6: JR TRAVAILLE | Q6: MT JOURNALIER | R6: JR TRAVAILLE | S6: MONTANT
B7: 1 | R7: =+SUM(P7,N7,L7,J7,H7,F7,D7) -> 0 | S7: =+SUM(E7,G7,I7,K7,M7,O7,Q7) -> 0 | U7: =+S7-T7 -> 0
B8: 2 | R8: =+SUM(P8,N8,L8,J8,H8,F8,D8) -> 0 | S8: =+SUM(E8,G8,I8,K8,M8,O8,Q8) -> 0 | U8: =+S8-T8 -> 0
B9: 3 | R9: =+SUM(P9,N9,L9,J9,H9,F9,D9) -> 0 | S9: =+SUM(E9,G9,I9,K9,M9,O9,Q9) -> 0 | U9: =+S9-T9 -> 0
B10: 4 | R10: =+SUM(P10,N10,L10,J10,H10,F10,D10) -> 0 | S10: =+SUM(E10,G10,I10,K10,M10,O10,Q10) -> 0 | U10: =+S10-T10 -> 0
B11: 5 | R11: =+SUM(P11,N11,L11,J11,H11,F11,D11) -> 0 | S11: =+SUM(E11,G11,I11,K11,M11,O11,Q11) -> 0 | U11: =+S11-T11 -> 0
B12: 6 | R12: =+SUM(P12,N12,L12,J12,H12,F12,D12) -> 0 | S12: =+SUM(E12,G12,I12,K12,M12,O12,Q12) -> 0 | U12: =+S12-T12 -> 0
B13: 7 | R13: =+SUM(P13,N13,L13,J13,H13,F13,D13) -> 0 | S13: =+SUM(E13,G13,I13,K13,M13,O13,Q13) -> 0 | U13: =+S13-T13 -> 0
B14: 8 | R14: =+SUM(P14,N14,L14,J14,H14,F14,D14) -> 0 | S14: =+SUM(E14,G14,I14,K14,M14,O14,Q14) -> 0 | U14: =+S14-T14 -> 0
B15: 9 | R15: =+SUM(P15,N15,L15,J15,H15,F15,D15) -> 0 | S15: =+SUM(E15,G15,I15,K15,M15,O15,Q15) -> 0 | U15: =+S15-T15 -> 0
B16: 10 | R16: =+SUM(P16,N16,L16,J16,H16,F16,D16) -> 0 | S16: =+SUM(E16,G16,I16,K16,M16,O16,Q16) -> 0 | U16: =+S16-T16 -> 0
B17: 11 | R17: =+SUM(P17,N17,L17,J17,H17,F17,D17) -> 0 | S17: =+SUM(E17,G17,I17,K17,M17,O17,Q17) -> 0 | U17: =+S17-T17 -> 0
B18: 12 | R18: =+SUM(P18,N18,L18,J18,H18,F18,D18) -> 0 | S18: =+SUM(E18,G18,I18,K18,M18,O18,Q18) -> 0 | U18: =+S18-T18 -> 0
... B30: 24 | R30: =+SUM(P30,N30,L30,J30,H30,F30,D30) -> 0 | S30: =+SUM(E30,G30,I30,K30,M30,O30,Q30) -> 0 | U30: =+S30-T30 -> 0
B31: Total | D31: =SUM(D7:D30) -> 0 | E31: =SUM(E7:E30) -> 0 | F31: =SUM(F7:F30) -> 0 | G31: =SUM(G7:G30) -> 0 | H31: =SUM(H7:H30) -> 0 | I31: =SUM(I7:I30) -> 0 | J31: =SUM(J7:J30) -> 0 | K31: =SUM(K7:K30) -> 0 | ... Q31: =SUM(Q7:Q30) -> 0 | R31: =+SUM(P31,N31,L31,J31,H31,F31,D31) -> 0 | S31: =+SUM(E31,G31,I31,K31,M31,O31,Q31) -> 0 | T31: =SUBTOTAL(109,MACONS!$T$7:$T$30) -> 0 | U31: =SUBTOTAL(109,MACONS!$U$7:$U$30) -> 197500
P33: Check | R33: =+MACONS!$R$31-SUM('SUIVI HEBDOMADAIRE PAIE'!D7,'SUIVI HEBDOMADAIRE PAIE'!F7,'SUIVI HEBDOMADAIRE PAIE'!H7,'SUIVI HEBDOMADAIRE PAIE'!J7,'SUIVI HEBDOMADAIRE PAIE'!L7,'SUIVI HEBDOMADAIRE PAIE'!N7,'SUIVI HEBDOMADAIRE PAIE'!P7) -> 0

Sheet OPERATEUR BETONNIERE
B3: FICHE D'EMARGEMENT DES OPERATEURS BETONNIERES / SEMAINE DU 03/07/2026 AU 09/07/2026
B5: S/N | C5: NOM ET PRENOMS | D5: VENDREDI | F5: SAMEDI | H5: DIMANCHE | J5: LUNDI | L5: MARDI | N5: MERCREDI | P5: JEUDI | R5: TOTAL | T5: RETENUE EPI | U5: NET A PAYER
D6: JR TRAVAILLE | E6: MT JOURNALIER | F6: JR TRAVAILLE | G6: MT JOURNALIER | H6: JR TRAVAILLE | I6: MT JOURNALIER | J6: JR TRAVAILLE | K6: MT JOURNALIER | L6: JR TRAVAILLE | M6: MT JOURNALIER | N6: JR TRAVAILLE | O6: MT JOURNALIER | P6: JR TRAVAILLE | Q6: MT JOURNALIER | R6: JR TRAVAILLE | S6: MONTANT
B7: 1 | C7: KAMATE YACOU | D7: 1 | E7: 7500 | F7: 1 | G7: 7500 | J7: 1 | K7: 7500 | L7: 1 | M7: 7500 | N7: 1 | O7: 7500 | P7: 1 | Q7: 7500 | R7: =+SUM(P7,N7,L7,J7,H7,F7,D7) -> 6 | S7: =+SUM(E7,G7,I7,K7,M7,O7,Q7) -> 45000 | U7: =+S7-T7 -> 45000
B8: 2 | C8: BAKAYOKO JEAN MARC | D8: 1 | E8: 7500 | F8: 1 | G8: 7500 | J8: 0 | K8: 0 | L8: 0 | M8: 0 | N8: 0 | O8: 0 | P8: 0 | Q8: 0 | R8: =+SUM(P8,N8,L8,J8,H8,F8,D8) -> 2 | S8: =+SUM(E8,G8,I8,K8,M8,O8,Q8) -> 15000 | U8: =+S8-T8 -> 15000
B9: 3 | R9: =+SUM(P9,N9,L9,J9,H9,F9,D9) -> 0 | S9: =+SUM(E9,G9,I9,K9,M9,O9,Q9) -> 0 | U9: =+S9-T9 -> 0
B10: 4 | R10: =+SUM(P10,N10,L10,J10,H10,F10,D10) -> 0 | S10: =+SUM(E10,G10,I10,K10,M10,O10,Q10) -> 0 | U10: =+S10-T10 -> 0
B11: 5 | R11: =+SUM(P11,N11,L11,J11,H11,F11,D11) -> 0 | S11: =+SUM(E11,G11,I11,K11,M11,O11,Q11) -> 0 | U11: =+S11-T11 -> 0
B12: 6 | R12: =+SUM(P12,N12,L12,J12,H12,F12,D12) -> 0 | S12: =+SUM(E12,G12,I12,K12,M12,O12,Q12) -> 0 | U12: =+S12-T12 -> 0
B13: 7 | R13: =+SUM(P13,N13,L13,J13,H13,F13,D13) -> 0 | S13: =+SUM(E13,G13,I13,K13,M13,O13,Q13) -> 0 | U13: =+S13-T13 -> 0
B14: 8 | R14: =+SUM(P14,N14,L14,J14,H14,F14,D14) -> 0 | S14: =+SUM(E14,G14,I14,K14,M14,O14,Q14) -> 0 | U14: =+S14-T14 -> 0
B15: 9 | R15: =+SUM(P15,N15,L15,J15,H15,F15,D15) -> 0 | S15: =+SUM(E15,G15,I15,K15,M15,O15,Q15) -> 0 | U15: =+S15-T15 -> 0
B16: 10 | R16: =+SUM(P16,N16,L16,J16,H16,F16,D16) -> 0 | S16: =+SUM(E16,G16,I16,K16,M16,O16,Q16) -> 0 | U16: =+S16-T16 -> 0
B17: 11 | R17: =+SUM(P17,N17,L17,J17,H17,F17,D17) -> 0 | S17: =+SUM(E17,G17,I17,K17,M17,O17,Q17) -> 0 | U17: =+S17-T17 -> 0
B18: 12 | R18: =+SUM(P18,N18,L18,J18,H18,F18,D18) -> 0 | S18: =+SUM(E18,G18,I18,K18,M18,O18,Q18) -> 0 | U18: =+S18-T18 -> 0
B19: 13 | R19: =+SUM(P19,N19,L19,J19,H19,F19,D19) -> 0 | S19: =+SUM(E19,G19,I19,K19,M19,O19,Q19) -> 0 | U19: =+S19-T19 -> 0
B20: 14 | R20: =+SUM(P20,N20,L20,J20,H20,F20,D20) -> 0 | S20: =+SUM(E20,G20,I20,K20,M20,O20,Q20) -> 0 | U20: =+S20-T20 -> 0
... B30: 24 | R30: =+SUM(P30,N30,L30,J30,H30,F30,D30) -> 0 | S30: =+SUM(E30,G30,I30,K30,M30,O30,Q30) -> 0 | U30: =+S30-T30 -> 0
B31: Total | D31: =SUM(D7:D30) -> 2 | E31: =SUM(E7:E30) -> 15000 | F31: =SUM(F7:F30) -> 2 | G31: =SUM(G7:G30) -> 15000 | H31: =SUM(H7:H30) -> 0 | I31: =SUM(I7:I30) -> 0 | J31: =SUM(J7:J30) -> 1 | K31: =SUM(K7:K30) -> 7500 | ... Q31: =SUM(Q7:Q30) -> 7500 | R31: =+SUM(P31,N31,L31,J31,H31,F31,D31) -> 8 | S31: =+SUM(E31,G31,I31,K31,M31,O31,Q31) -> 60000 | T31: =SUBTOTAL(109,MACONS!$T$7:$T$30) -> 0 | U31: =SUBTOTAL(109,MACONS!$U$7:$U$30) -> 197500
P33: Check | R33: =+MACONS!$R$31-SUM('SUIVI HEBDOMADAIRE PAIE'!D7,'SUIVI HEBDOMADAIRE PAIE'!F7,'SUIVI HEBDOMADAIRE PAIE'!H7,'SUIVI HEBDOMADAIRE PAIE'!J7,'SUIVI HEBDOMADAIRE PAIE'!L7,'SUIVI HEBDOMADAIRE PAIE'!N7,'SUIVI HEBDOMADAIRE PAIE'!P7) -> 0

Sheet AIDE CHANTIER
B3: FICHE D'EMARGEMENT DES AIDES CHANTIERS / SEMAINE DU 03/07/2026 AU 09/07/2026
B5: S/N | C5: NOM ET PRENOMS | D5: VENDREDI | F5: SAMEDI | H5: DIMANCHE | J5: LUNDI | L5: MARDI | N5: MERCREDI | P5: JEUDI | R5: TOTAL | T5: RETENUE EPI | U5: NET A PAYER
D6: JR TRAVAILLE | E6: MT JOURNALIER | F6: JR TRAVAILLE | G6: MT JOURNALIER | H6: JR TRAVAILLE | I6: MT JOURNALIER | J6: JR TRAVAILLE | K6: MT JOURNALIER | L6: JR TRAVAILLE | M6: MT JOURNALIER | N6: JR TRAVAILLE | O6: MT JOURNALIER | P6: JR TRAVAILLE | Q6: MT JOURNALIER | R6: JR TRAVAILLE | S6: MONTANT
B7: 1 | C7: KAHOU BI AMBROISE | D7: 0 | E7: 0 | F7: 0 | G7: 0 | J7: 0 | K7: 0 | L7: 0 | M7: 0 | N7: 0 | O7: 0 | P7: 0 | Q7: 0 | R7: =+SUM(P7,N7,L7,J7,H7,F7,D7) -> 0 | S7: =+SUM(E7,G7,I7,K7,M7,O7,Q7) -> 0 | U7: =+S7-T7 -> 0
B8: 2 | C8: NDRI YAO CONSTANT | D8: 0 | E8: 0 | F8: 1 | G8: 4500 | J8: 0 | K8: 0 | L8: 0 | M8: 0 | N8: 0 | O8: 0 | P8: 0 | Q8: 0 | R8: =+SUM(P8,N8,L8,J8,H8,F8,D8) -> 1 | S8: =+SUM(E8,G8,I8,K8,M8,O8,Q8) -> 4500 | U8: =+S8-T8 -> 4500
B9: 3 | C9: BANE MARIUS | D9: 1 | E9: 4500 | F9: 1 | G9: 4500 | J9: 1 | K9: 4500 | L9: 0 | M9: 0 | N9: 0 | O9: 0 | P9: 0 | Q9: 0 | R9: =+SUM(P9,N9,L9,J9,H9,F9,D9) -> 3 | S9: =+SUM(E9,G9,I9,K9,M9,O9,Q9) -> 13500 | U9: =+S9-T9 -> 13500
B10: 4 | C10: KOUAKOU KOUASSI NOEL | D10: 1 | E10: 4500 | F10: 1 | G10: 4500 | J10: 1 | K10: 4500 | L10: 1 | M10: 4500 | N10: 1 | O10: 4500 | P10: 1 | Q10: 4500 | R10: =+SUM(P10,N10,L10,J10,H10,F10,D10) -> 6 | S10: =+SUM(E10,G10,I10,K10,M10,O10,Q10) -> 27000 | U10: =+S10-T10 -> 27000
B11: 5 | C11: KOUASSI KOUADIO KEVIN | D11: 1 | E11: 4500 | F11: 1 | G11: 4500 | J11: 1 | K11: 4500 | L11: 1 | M11: 4500 | N11: 1 | O11: 4500 | P11: 1 | Q11: 4500 | R11: =+SUM(P11,N11,L11,J11,H11,F11,D11) -> 6 | S11: =+SUM(E11,G11,I11,K11,M11,O11,Q11) -> 27000 | U11: =+S11-T11 -> 27000
B12: 6 | C12: DJE BI ROMARIC | D12: 1 | E12: 4500 | F12: 1 | G12: 4500 | J12: 1 | K12: 4500 | L12: 1 | M12: 4500 | N12: 1 | O12: 4500 | P12: 0 | Q12: 0 | R12: =+SUM(P12,N12,L12,J12,H12,F12,D12) -> 5 | S12: =+SUM(E12,G12,I12,K12,M12,O12,Q12) -> 22500 | U12: =+S12-T12 -> 22500
B13: 7 | C13: DOUMBIA ISMAEL | D13: 1 | E13: 4500 | F13: 1 | G13: 4500 | J13: 1 | K13: 4500 | L13: 1 | M13: 4500 | N13: 1 | O13: 4500 | P13: 1 | Q13: 4500 | R13: =+SUM(P13,N13,L13,J13,H13,F13,D13) -> 6 | S13: =+SUM(E13,G13,I13,K13,M13,O13,Q13) -> 27000 | U13: =+S13-T13 -> 27000
B14: 8 | C14: TIE BI TIE SYLVA | D14: 0 | E14: 0 | F14: 0 | G14: 0 | J14: 1 | K14: 4500 | L14: 1 | M14: 4500 | N14: 1 | O14: 4500 | P14: 1 | Q14: 4500 | R14: =+SUM(P14,N14,L14,J14,H14,F14,D14) -> 4 | S14: =+SUM(E14,G14,I14,K14,M14,O14,Q14) -> 18000 | U14: =+S14-T14 -> 18000
B15: 9 | C15: AKWAEZE ANTONY | D15: 1 | E15: 4500 | F15: 1 | G15: 4500 | J15: 1 | K15: 4500 | L15: 1 | M15: 4500 | N15: 1 | O15: 4500 | P15: 0 | Q15: 0 | R15: =+SUM(P15,N15,L15,J15,H15,F15,D15) -> 5 | S15: =+SUM(E15,G15,I15,K15,M15,O15,Q15) -> 22500 | U15: =+S15-T15 -> 22500
B16: 10 | C16: LYKA GOUELY | D16: 1 | E16: 4500 | F16: 1 | G16: 4500 | J16: 0 | K16: 0 | L16: 0 | M16: 0 | N16: 1 | O16: 4500 | P16: 1 | Q16: 4500 | R16: =+SUM(P16,N16,L16,J16,H16,F16,D16) -> 4 | S16: =+SUM(E16,G16,I16,K16,M16,O16,Q16) -> 18000 | U16: =+S16-T16 -> 18000
B17: 11 | C17: TRA BI FIDEL | D17: 0 | E17: 0 | F17: 0 | G17: 0 | J17: 0 | K17: 0 | L17: 0 | M17: 0 | N17: 0 | O17: 0 | P17: 0 | Q17: 0 | R17: =+SUM(P17,N17,L17,J17,H17,F17,D17) -> 0 | S17: =+SUM(E17,G17,I17,K17,M17,O17,Q17) -> 0 | U17: =+S17-T17 -> 0
B18: 12 | C18: BAKAYOKO AICHA | D18: 1 | E18: 4500 | F18: 1 | G18: 4500 | J18: 0 | K18: 0 | L18: 1 | M18: 4500 | N18: 1 | O18: 4500 | P18: 1 | Q18: 4500 | R18: =+SUM(P18,N18,L18,J18,H18,F18,D18) -> 5 | S18: =+SUM(E18,G18,I18,K18,M18,O18,Q18) -> 22500 | U18: =+S18-T18 -> 22500
... B31: 25 | C31: NGUESSAN KOUADIO KEVIN | D31: 0 | E31: 0 | F31: 0 | G31: 0 | J31: 0 | K31: 0 | L31: 0 | M31: 0 | N31: 0 | O31: 0 | P31: 0 | Q31: 0 | R31: =+SUM(P31,N31,L31,J31,H31,F31,D31) -> 0 | S31: =+SUM(E31,G31,I31,K31,M31,O31,Q31) -> 0 | U31: =+S31-T31 -> 0
B32: 26 | C32: KONE ISMAEL | D32: 0 | E32: 0 | F32: 0 | G32: 0 | J32: 0 | K32: 0 | L32: 0 | M32: 0 | N32: 0 | P32: 0 | Q32: 0 | R32: =+SUM(P32,N32,L32,J32,H32,F32,D32) -> 0 | S32: =+SUM(E32,G32,I32,K32,M32,O32,Q32) -> 0 | U32: =+S32-T32 -> 0
B33: 27 | C33: ZOYA EVARIST | D33: 1 | E33: 4500 | F33: 1 | G33: 4500 | J33: 0 | K33: 0 | L33: 0 | M33: 0 | N33: 0 | O33: 0 | P33: 0 | Q33: 0 | R33: =+SUM(P33,N33,L33,J33,H33,F33,D33) -> 2 | S33: =+SUM(E33,G33,I33,K33,M33,O33,Q33) -> 9000 | U33: =+S33-T33 -> 9000
B34: 28 | C34: IRIE BI TRA RODOLPH | D34: 1 | E34: 4500 | F34: 1 | G34: 4500 | J34: 1 | K34: 4500 | L34: 1 | M34: 4500 | N34: 1 | O34: 4500 | P34: 1 | Q34: 4500 | R34: =+SUM(P34,N34,L34,J34,H34,F34,D34) -> 6 | S34: =+SUM(E34,G34,I34,K34,M34,O34,Q34) -> 27000 | U34: =+S34-T34 -> 27000
B35: 29 | C35: IRIE BI BOH MARCEL | D35: 1 | E35: 4500 | F35: 1 | G35: 4500 | J35: 1 | K35: 4500 | L35: 1 | M35: 4500 | N35: 1 | O35: 4500 | P35: 1 | Q35: 4500 | R35: =+SUM(P35,N35,L35,J35,H35,F35,D35) -> 6 | S35: =+SUM(E35,G35,I35,K35,M35,O35,Q35) -> 27000 | U35: =+S35-T35 -> 27000
B36: 30 | C36: AGBASSI LOBA BASILE | D36: 1 | E36: 4500 | F36: 0 | G36: 0 | J36: 0 | K36: 0 | L36: 0 | M36: 0 | N36: 0 | O36: 0 | P36: 0 | Q36: 0 | R36: =+SUM(P36,N36,L36,J36,H36,F36,D36) -> 1 | S36: =+SUM(E36,G36,I36,K36,M36,O36,Q36) -> 4500 | U36: =+S36-T36 -> 4500
B37: 31 | C37: ASSEMON VERDIER | D37: 1 | E37: 4500 | F37: 1 | G37: 4500 | J37: 1 | K37: 4500 | L37: 1 | M37: 4500 | N37: 0.5 | O37: 2250 | P37: 1 | Q37: 4500 | R37: =+SUM(P37,N37,L37,J37,H37,F37,D37) -> 5.5 | S37: =+SUM(E37,G37,I37,K37,M37,O37,Q37) -> 24750 | U37: =+S37-T37 -> 24750
B38: 32 | C38: DJOSSOU BRICE | D38: 0 | E38: 0 | F38: 0 | G38: 0 | J38: 0 | K38: 0 | L38: 0 | M38: 0 | N38: 0 | O38: 0 | P38: 0 | Q38: 0 | R38: =+SUM(P38,N38,L38,J38,H38,F38,D38) -> 0 | S38: =+SUM(E38,G38,I38,K38,M38,O38,Q38) -> 0 | U38: =+S38-T38 -> 0
B39: 33 | C39: DJE BI BOH ALEXANDRE | J39: 1 | K39: 4500 | L39: 1 | M39: 4500 | N39: 1 | O39: 4500 | P39: 1 | Q39: 4500 | R39: =+SUM(P39,N39,L39,J39,H39,F39,D39) -> 4 | S39: =+SUM(E39,G39,I39,K39,M39,O39,Q39) -> 18000 | U39: =+S39-T39 -> 18000
B40: 34 | R40: =+SUM(P40,N40,L40,J40,H40,F40,D40) -> 0 | S40: =+SUM(E40,G40,I40,K40,M40,O40,Q40) -> 0 | U40: =+S40-T40 -> 0
B41: 35 | R41: =+SUM(P41,N41,L41,J41,H41,F41,D41) -> 0 | S41: =+SUM(E41,G41,I41,K41,M41,O41,Q41) -> 0 | U41: =+S41-T41 -> 0
B42: 36 | R42: =+SUM(P42,N42,L42,J42,H42,F42,D42) -> 0 | S42: =+SUM(E42,G42,I42,K42,M42,O42,Q42) -> 0 | U42: =+S42-T42 -> 0
B43: 37 | R43: =+SUM(P43,N43,L43,J43,H43,F43,D43) -> 0 | S43: =+SUM(E43,G43,I43,K43,M43,O43,Q43) -> 0 | U43: =+S43-T43 -> 0
B44: 38 | R44: =+SUM(P44,N44,L44,J44,H44,F44,D44) -> 0 | S44: =+SUM(E44,G44,I44,K44,M44,O44,Q44) -> 0 | U44: =+S44-T44 -> 0
B45: 39 | R45: =+SUM(P45,N45,L45,J45,H45,F45,D45) -> 0 | S45: =+SUM(E45,G45,I45,K45,M45,O45,Q45) -> 0 | U45: =+S45-T45 -> 0
B46: 40 | R46: =+SUM(P46,N46,L46,J46,H46,F46,D46) -> 0 | S46: =+SUM(E46,G46,I46,K46,M46,O46,Q46) -> 0 | U46: =+S46-T46 -> 0
B47: 41 | R47: =+SUM(P47,N47,L47,J47,H47,F47,D47) -> 0 | S47: =+SUM(E47,G47,I47,K47,M47,O47,Q47) -> 0 | U47: =+S47-T47 -> 0
B48: 42 | R48: =+SUM(P48,N48,L48,J48,H48,F48,D48) -> 0 | S48: =+SUM(E48,G48,I48,K48,M48,O48,Q48) -> 0 | U48: =+S48-T48 -> 0
B49: 43 | R49: =+SUM(P49,N49,L49,J49,H49,F49,D49) -> 0 | S49: =+SUM(E49,G49,I49,K49,M49,O49,Q49) -> 0 | U49: =+S49-T49 -> 0
B50: 44 | R50: =+SUM(P50,N50,L50,J50,H50,F50,D50) -> 0 | S50: =+SUM(E50,G50,I50,K50,M50,O50,Q50) -> 0 | U50: =+S50-T50 -> 0
B51: 45 | R51: =+SUM(P51,N51,L51,J51,H51,F51,D51) -> 0 | S51: =+SUM(E51,G51,I51,K51,M51,O51,Q51) -> 0 | U51: =+S51-T51 -> 0
... B57: 51 | R57: =+SUM(P57,N57,L57,J57,H57,F57,D57) -> 0 | S57: =+SUM(E57,G57,I57,K57,M57,O57,Q57) -> 0 | U57: =+S57-T57 -> 0
B58: Total | D58: =SUM(D7:D57) -> 23 | E58: =SUM(E7:E57) -> 103500 | F58: =SUM(F7:F57) -> 20 | G58: =SUM(G7:G57) -> 90000 | H58: =SUM(H7:H57) -> 0 | I58: =SUM(I7:I57) -> 0 | J58: =SUM(J7:J57) -> 22 | K58: =SUM(K7:K57) -> 99000 | ... Q58: =SUM(Q7:Q57) -> 90000 | R58: =+SUM(P58,N58,L58,J58,H58,F58,D58) -> 129.5 | S58: =+SUM(E58,G58,I58,K58,M58,O58,Q58) -> 582750 | T58: =SUBTOTAL(109,MACONS!$T$7:$T$30) -> 0 | U58: =SUBTOTAL(109,MACONS!$U$7:$U$30) -> 197500
P60: Check | R60: =+MACONS!$R$31-SUM('SUIVI HEBDOMADAIRE PAIE'!D7,'SUIVI HEBDOMADAIRE PAIE'!F7,'SUIVI HEBDOMADAIRE PAIE'!H7,'SUIVI HEBDOMADAIRE PAIE'!J7,'SUIVI HEBDOMADAIRE PAIE'!L7,'SUIVI HEBDOMADAIRE PAIE'!N7,'SUIVI HEBDOMADAIRE PAIE'!P7) -> 0

Sheet HEURES SUP
B3: FICHE D'EMARGEMENT DES HEURES SUP/ SEMAINE DU 03/07/2026 AU 09/07/2026
B5: S/N | C5: NOM ET PRENOMS | D5: VENDREDI | F5: SAMEDI | H5: DIMANCHE | J5: LUNDI | L5: MARDI | N5: MERCREDI | P5: JEUDI | R5: TOTAL | T5: RETENUE EPI | U5: NET A PAYER
D6: JR TRAVAILLE | E6: MT JOURNALIER | F6: JR TRAVAILLE | G6: MT JOURNALIER | H6: JR TRAVAILLE | I6: MT JOURNALIER | J6: JR TRAVAILLE | K6: MT JOURNALIER | L6: JR TRAVAILLE | M6: MT JOURNALIER | N6: JR TRAVAILLE | O6: MT JOURNALIER | P6: JR TRAVAILLE | Q6: MT JOURNALIER | R6: JR TRAVAILLE | S6: MONTANT
B7: 1 | C7: EKISSI PRINCE | G7: 646.875 | R7: =+SUM(P7,N7,L7,J7,H7,F7,D7) -> 0 | S7: =+SUM(E7,G7,I7,K7,M7,O7,Q7) -> 646.875 | U7: =+S7-T7 -> 646.875
B8: 2 | C8: BANE MARIUS | G8: 646.875 | R8: =+SUM(P8,N8,L8,J8,H8,F8,D8) -> 0 | S8: =+SUM(E8,G8,I8,K8,M8,O8,Q8) -> 646.875 | U8: =+S8-T8 -> 646.875
B9: 3 | C9: DOUMBIA ISMAEL | G9: 646.875 | R9: =+SUM(P9,N9,L9,J9,H9,F9,D9) -> 0 | S9: =+SUM(E9,G9,I9,K9,M9,O9,Q9) -> 646.875 | U9: =+S9-T9 -> 646.875
B10: 4 | C10: KOUADIO JEAN PRIVAT | G10: 1221.875 | R10: =+SUM(P10,N10,L10,J10,H10,F10,D10) -> 0 | S10: =+SUM(E10,G10,I10,K10,M10,O10,Q10) -> 1221.875 | U10: =+S10-T10 -> 1221.875
B11: 5 | C11: YATTE BORIS | G11: 1078.125 | R11: =+SUM(P11,N11,L11,J11,H11,F11,D11) -> 0 | S11: =+SUM(E11,G11,I11,K11,M11,O11,Q11) -> 1078.125 | U11: =+S11-T11 -> 1078.125
B12: 6 | C12: OULAI ARNAUD | G12: 1078.125 | R12: =+SUM(P12,N12,L12,J12,H12,F12,D12) -> 0 | S12: =+SUM(E12,G12,I12,K12,M12,O12,Q12) -> 1078.125 | U12: =+S12-T12 -> 1078.125
B13: 7 | C13: DIOMANDE FRANCK | G13: 1078.125 | R13: =+SUM(P13,N13,L13,J13,H13,F13,D13) -> 0 | S13: =+SUM(E13,G13,I13,K13,M13,O13,Q13) -> 1078.125 | U13: =+S13-T13 -> 1078.125
B14: 8 | C14: TOKPA CHERIF | G14: 1078.125 | R14: =+SUM(P14,N14,L14,J14,H14,F14,D14) -> 0 | S14: =+SUM(E14,G14,I14,K14,M14,O14,Q14) -> 1078.125 | U14: =+S14-T14 -> 1078.125
B15: 9 | C15: BLE ARMEL | G15: 1078.125 | R15: =+SUM(P15,N15,L15,J15,H15,F15,D15) -> 0 | S15: =+SUM(E15,G15,I15,K15,M15,O15,Q15) -> 1078.125 | U15: =+S15-T15 -> 1078.125
B16: 10 | C16: GOGBEU EUDES | G16: 1078.125 | R16: =+SUM(P16,N16,L16,J16,H16,F16,D16) -> 0 | S16: =+SUM(E16,G16,I16,K16,M16,O16,Q16) -> 1078.125 | U16: =+S16-T16 -> 1078.125
B17: 11 | R17: =+SUM(P17,N17,L17,J17,H17,F17,D17) -> 0 | S17: =+SUM(E17,G17,I17,K17,M17,O17,Q17) -> 0 | U17: =+S17-T17 -> 0
B18: 12 | R18: =+SUM(P18,N18,L18,J18,H18,F18,D18) -> 0 | S18: =+SUM(E18,G18,I18,K18,M18,O18,Q18) -> 0 | U18: =+S18-T18 -> 0
B19: 13 | R19: =+SUM(P19,N19,L19,J19,H19,F19,D19) -> 0 | S19: =+SUM(E19,G19,I19,K19,M19,O19,Q19) -> 0 | U19: =+S19-T19 -> 0
B20: 14 | R20: =+SUM(P20,N20,L20,J20,H20,F20,D20) -> 0 | S20: =+SUM(E20,G20,I20,K20,M20,O20,Q20) -> 0 | U20: =+S20-T20 -> 0
B21: 15 | R21: =+SUM(P21,N21,L21,J21,H21,F21,D21) -> 0 | S21: =+SUM(E21,G21,I21,K21,M21,O21,Q21) -> 0 | U21: =+S21-T21 -> 0
B22: 16 | R22: =+SUM(P22,N22,L22,J22,H22,F22,D22) -> 0 | S22: =+SUM(E22,G22,I22,K22,M22,O22,Q22) -> 0 | U22: =+S22-T22 -> 0
B23: 17 | R23: =+SUM(P23,N23,L23,J23,H23,F23,D23) -> 0 | S23: =+SUM(E23,G23,I23,K23,M23,O23,Q23) -> 0 | U23: =+S23-T23 -> 0
B24: 18 | R24: =+SUM(P24,N24,L24,J24,H24,F24,D24) -> 0 | S24: =+SUM(E24,G24,I24,K24,M24,O24,Q24) -> 0 | U24: =+S24-T24 -> 0
B25: 19 | R25: =+SUM(P25,N25,L25,J25,H25,F25,D25) -> 0 | S25: =+SUM(E25,G25,I25,K25,M25,O25,Q25) -> 0 | U25: =+S25-T25 -> 0
B26: 20 | R26: =+SUM(P26,N26,L26,J26,H26,F26,D26) -> 0 | S26: =+SUM(E26,G26,I26,K26,M26,O26,Q26) -> 0 | U26: =+S26-T26 -> 0
B27: 21 | R27: =+SUM(P27,N27,L27,J27,H27,F27,D27) -> 0 | S27: =+SUM(E27,G27,I27,K27,M27,O27,Q27) -> 0 | U27: =+S27-T27 -> 0
B28: 22 | R28: =+SUM(P28,N28,L28,J28,H28,F28,D28) -> 0 | S28: =+SUM(E28,G28,I28,K28,M28,O28,Q28) -> 0 | U28: =+S28-T28 -> 0
... B57: 51 | R57: =+SUM(P57,N57,L57,J57,H57,F57,D57) -> 0 | S57: =+SUM(E57,G57,I57,K57,M57,O57,Q57) -> 0 | U57: =+S57-T57 -> 0
B58: Total | D58: =SUM(D7:D57) -> 0 | E58: =SUM(E7:E57) -> 0 | F58: =SUM(F7:F57) -> 0 | G58: =SUM(G7:G57) -> 9631.25 | H58: =SUM(H7:H57) -> 0 | I58: =SUM(I7:I57) -> 0 | J58: =SUM(J7:J57) -> 0 | K58: =SUM(K7:K57) -> 0 | ... Q58: =SUM(Q7:Q57) -> 0 | R58: =+SUM(P58,N58,L58,J58,H58,F58,D58) -> 0 | S58: =+SUM(E58,G58,I58,K58,M58,O58,Q58) -> 9631.25 | T58: =SUBTOTAL(109,MACONS!$T$7:$T$30) -> 0 | U58: =SUBTOTAL(109,MACONS!$U$7:$U$30) -> 197500
P60: Check | R60: =+MACONS!$R$31-SUM('SUIVI HEBDOMADAIRE PAIE'!D7,'SUIVI HEBDOMADAIRE PAIE'!F7,'SUIVI HEBDOMADAIRE PAIE'!H7,'SUIVI HEBDOMADAIRE PAIE'!J7,'SUIVI HEBDOMADAIRE PAIE'!L7,'SUIVI HEBDOMADAIRE PAIE'!N7,'SUIVI HEBDOMADAIRE PAIE'!P7) -> 0
